<?xml version="1.0"?>
<robot xmlns:xacro="http://www.ros.org/wiki/xacro"> 

<xacro:include filename="inertial_macros.xacro"/>

<material name="white">
    <color rgba="1 1 1 1" />
</material>

<material name="orange">
    <color rgba="1 0.3 0.1 1" />
</material>

<material name="blue">
    <color rgba="0.2 0.2 1 1" />
</material>

<material name="black">
    <color rgba="0 0 0 1" />
</material>

<material name="yellow">
    <color rgba="1 1 0 0" />
</material>

<material name="green">
    <color rgba="0 1 0 1" />
</material>

<material name="red">
    <color rgba="1 0 0 1" />
</material>

<link name="base_link">

</link>

<joint name="base_footprint_joint" type="fixed">
    <parent link="base_link"/>
    <child link="base_footprint"/>
    <origin xyz="0 0 0" rpy="0 0 0"/>
</joint>

<link name="base_footprint">
</link>

<joint name="chassis_wheel_joint" type="fixed">
    <parent link="base_link"/>
    <child link="base_chassis_wheel"/>
    <origin xyz="0 0 0"/> 
</joint>

<link name="base_chassis_wheel">
    <visual>
        <origin xyz="0 0 0" rpy="0 0 0"/>
        <geometry>
            <box size="0.40 0.40 0.02"/>
        </geometry>
        <material name="orange"/>
    </visual>
    <collision>
        <origin xyz="0 0 0" rpy="0 0 0"/>
        <geometry>
            <box size="0.40 0.40 0.02"/>
        </geometry>
    </collision>
    <inertial>
        <mass value="0.5"/>
        <origin xyz="0 0 0" rpy="0 0 0"/>
        <inertia ixx="0.001" iyy="0.001" izz="0.001" ixy="0.0" ixz="0.0" iyz="0.0"/>
    </inertial>
    
</link>

<gazebo reference="base_chassis_wheel">
    <material>Gazebo/Orange</material>
</gazebo>

<joint name="right_wheel_joint" type="continuous">
    <parent link="base_link"/>
    <child link="right_wheel"/>
    <origin xyz="0 -0.22 0" rpy="1.57 0 0"/>
    <axis xyz="0 0 -1"/>
</joint>

<link name="right_wheel">
    <visual>    
        <geometry>
            <cylinder radius="0.065" length="0.04"/>
        </geometry>
        <material name="green"/>
    </visual>
    <collision>    
        <geometry>
            <cylinder radius="0.065" length="0.04"/>
        </geometry>
    </collision>
    <xacro:inertial_cylinder mass="1.95" length="0.04" radius="0.065">
            <origin xyz="0 0 0" rpy="0 0 0"/>
    </xacro:inertial_cylinder>
</link>

<gazebo reference="right_wheel">
    <material>Gazebo/Green</material>
</gazebo>

<joint name="left_wheel_joint" type="continuous">
    <parent link="base_link"/>
    <child link="left_wheel"/>
    <origin xyz="0 0.22 0" rpy="-1.57 0 0"/>
    <axis xyz="0 0 1"/>
</joint>

<link name="left_wheel">
    <visual>    
        <geometry>
            <cylinder radius="0.065" length="0.04"/>
        </geometry>
        <material name="green"/>
    </visual>
    <collision>    
        <geometry>
            <cylinder radius="0.065" length="0.04"/>
        </geometry>
    </collision>
    <xacro:inertial_cylinder mass="1.95" length="0.04" radius="0.065">
            <origin xyz="0 0 0" rpy="0 0 0"/>
    </xacro:inertial_cylinder>
</link>

<gazebo reference="left_wheel">
    <material>Gazebo/Green</material>
</gazebo>

<joint name="caster_wheel_front_joint" type="continuous">
    <parent link="base_chassis_wheel"/>
    <child link="caster_wheel_front"/>
    <origin xyz="0.15 0 -0.0325"  rpy="0 0 0"/>
    <axis xyz="0 1 1"/>
</joint>

<link name="caster_wheel_front">
    <visual>
        <geometry>
            <sphere radius="0.0325"/>
        </geometry>
        <material name="white"/>
    </visual>
    <collision>
        <geometry>
            <sphere radius="0.0325"/>
        </geometry>
    </collision>
    <xacro:inertial_sphere mass="0.2" radius="0.0325">
            <origin xyz="0 0 0" rpy="0 0 0"/>
    </xacro:inertial_sphere>
</link>

<gazebo reference="caster_wheel_front">
    <material>Gazebo/White</material>
</gazebo>

<joint name="caster_wheel_back_joint" type="continuous">
    <parent link="base_chassis_wheel"/>
    <child link="caster_wheel_back"/>
    <origin xyz="-0.15 0 -0.0325" rpy="0 0 0"/>
    <axis xyz="0 1 1"/>
</joint>

<link name="caster_wheel_back">
    <visual>
        <geometry>
            <sphere radius="0.0325"/>
        </geometry>
        <material name="white"/>
    </visual>
    <collision>
        <geometry>
            <sphere radius="0.0325"/>
        </geometry>
    </collision>
    <xacro:inertial_sphere mass="0.2" radius="0.0325">
            <origin xyz="0 0 0" rpy="0 0 0"/>
    </xacro:inertial_sphere>
</link>

<gazebo reference="caster_wheel_back">
    <material>Gazebo/White</material>
</gazebo>

<joint name="columnA_joint" type="fixed">
    <parent link="base_chassis_wheel"/>
    <child link="columnA"/>
    <origin xyz="-0.17 -0.17 0.21"/>
</joint>

<link name="columnA">
    <visual>
        <geometry>
            <box size="0.03 0.03 0.4"/>
        </geometry>
        <material name="white"/>
    </visual>
    <collision>
        <geometry>
            <box size="0.03 0.03 0.4"/>
        </geometry>
    </collision>
</link>

<joint name="columnB_joint" type="fixed">
    <parent link="base_chassis_wheel"/>
    <child link="columnB"/>
    <origin xyz="0.17 -0.17 0.21"/>
</joint>

<link name="columnB">
    <visual>
        <geometry>
            <box size="0.03 0.03 0.4"/>
        </geometry>
        <material name="white"/>
    </visual>
    <collision>
        <geometry>
            <box size="0.03 0.03 0.4"/>
        </geometry>
    </collision>
</link>

<joint name="columnC_joint" type="fixed">
    <parent link="base_chassis_wheel"/>
    <child link="columnC"/>
    <origin xyz="-0.17 0.17 0.21"/>
</joint>

<link name="columnC">
    <visual>
        <geometry>
            <box size="0.03 0.03 0.4"/>
        </geometry>
        <material name="white"/>
    </visual>
    <collision>
        <geometry>
            <box size="0.03 0.03 0.4"/>
        </geometry>
    </collision>
</link>

<joint name="columnD_joint" type="fixed">
    <parent link="base_chassis_wheel"/>
    <child link="columnD"/>
    <origin xyz="0.17 0.17 0.21"/>
</joint>

<link name="columnD">
    <visual>
        <geometry>
            <box size="0.03 0.03 0.4"/>
        </geometry>
        <material name="white"/>
    </visual>
    <collision>
        <geometry>
            <box size="0.03 0.03 0.4"/>
        </geometry>
    </collision>
</link>

<joint name="plateA_joint" type="fixed">
    <parent link="base_chassis_wheel"/>
    <child link="plateA"/>
    <origin xyz="0 0 0.21"/> 
</joint>

<link name="plateA">
    <visual>
        <origin xyz="0 0 0" rpy="0 0 0"/>
        <geometry>
            <box size="0.40 0.40 0.02"/>
        </geometry>
        <material name="orange"/>
    </visual>
    <collision>
        <origin xyz="0 0 0" rpy="0 0 0"/>
        <geometry>
            <box size="0.40 0.40 0.02"/>
        </geometry>
    </collision>
    <inertial>
        <mass value="0.5"/>
        <origin xyz="0 0 0" rpy="0 0 0"/>
        <inertia ixx="0.001" iyy="0.001" izz="0.001" ixy="0.0" ixz="0.0" iyz="0.0"/>
    </inertial>
    
</link>

<gazebo reference="plateA">
    <material>Gazebo/Orange</material>
</gazebo>
<!-- <joint name="plateA_joint" type="fixed">
    <parent link="base_chassis_wheel"/>
    <child link="plateA"/>
    <origin xyz="0 0 0.17"/>
</joint>

<link name="plateA">
    <visual>
        <geometry>
            <cylinder radius="0.15" length="0.015"/>
        </geometry>
        <material name="orange"/>
    </visual>
    <collision>
        <geometry>
            <cylinder radius="0.15" length="0.015"/>
        </geometry>
    </collision>
    <xacro:inertial_cylinder mass="0.3" length="0.015" radius="0.15">
            <origin xyz="0 0 0" rpy="0 0 0"/>
    </xacro:inertial_cylinder>
</link> -->

<!-- <gazebo reference="plateA">
    <material>Gazebo/Orange</material>
</gazebo> -->

<!-- <joint name="columnG_joint" type="fixed">
    <parent link="plateA"/>
    <child link="columnG"/>
    <origin xyz="0 -0.13 0.085"/>
</joint>

<link name="columnG">
    <visual>
        <geometry>
            <box size="0.05 0.01 0.15"/>
        </geometry>
        <material name="white"/>
    </visual>
    <collision>
        <geometry>
            <box size="0.05 0.01 0.15"/>
        </geometry>
    </collision>
</link>
<gazebo reference="columnG">
    <material>Gazebo/White</material>
</gazebo>

<joint name="columnH_joint" type="fixed">
    <parent link="plateA"/>
    <child link="columnH"/>
    <origin xyz="0 0.13 0.085"/>
</joint>

<link name="columnH">
    <visual>
        <geometry>
            <box size="0.05 0.01 0.15"/>
        </geometry>
        <material name="white"/>
    </visual>
    <collision>
        <geometry>
            <box size="0.05 0.01 0.15"/>
        </geometry>
    </collision>
</link>

<gazebo reference="columnH">
    <material>Gazebo/White</material>
</gazebo> -->

<joint name="Topplate_joint" type="fixed">
    <parent link="plateA"/>
    <child link="Topplate"/>
    <origin xyz="0 0 0.21"/> 
</joint>

<link name="Topplate">
    <visual>
        <origin xyz="0 0 0" rpy="0 0 0"/>
        <geometry>
            <box size="0.40 0.40 0.02"/>
        </geometry>
        <material name="orange"/>
    </visual>
    <collision>
        <origin xyz="0 0 0" rpy="0 0 0"/>
        <geometry>
            <box size="0.40 0.40 0.02"/>
        </geometry>
    </collision>
    <inertial>
        <mass value="0.5"/>
        <origin xyz="0 0 0" rpy="0 0 0"/>
        <inertia ixx="0.001" iyy="0.001" izz="0.001" ixy="0.0" ixz="0.0" iyz="0.0"/>
    </inertial>
    
</link>

<gazebo reference="Topplate">
    <material>Gazebo/Orange</material>
</gazebo>


<!-- <joint name="Topplate_joint" type="fixed">
    <parent link="plateA"/>
    <child link="Topplate"/>
    <origin xyz="0 0 0.155"/>
</joint>

<link name="Topplate">
    <visual>
        <geometry>
            <cylinder radius="0.15" length="0.01"/>
        </geometry>
        <material name="green"/>
    </visual>
    <collision>
        <geometry>
            <cylinder radius="0.15" length="0.01"/>
        </geometry>
    </collision>
    <xacro:inertial_cylinder mass="0.2" length="0.01" radius="0.15">
            <origin xyz="0 0 0" rpy="0 0 0"/>
    </xacro:inertial_cylinder>
</link>

<gazebo reference="Topplate">
    <material>Gazebo/Green</material>
</gazebo> -->


</robot>